<?xml version="1.0" ?>
<!-- =================================================================================== -->
<!-- |    This document was autogenerated by xacro from adl200_description.urdf.xacro  | -->
<!-- |    EDITING THIS FILE BY HAND IS NOT RECOMMENDED                                 | -->
<!-- =================================================================================== -->
<robot name="robot">
  <material name="white">
    <color rgba="1 1 1 1"/>
  </material>
  <material name="orange">
    <color rgba="1 0.3 0.1 1"/>
  </material>
  <material name="blue">
    <color rgba="0.2 0.2 1 1"/>
  </material>
  <material name="black">
    <color rgba="0 0 0 1"/>
  </material>
  <!--BASE LINK-->
  <link name="base_link">
    </link>
  <!--CHASSIS LINK-->
  <joint name="chassis_joint" type="fixed">
    <parent link="base_link"/>
    <child link="chassis"/>
    <origin xyz="0 0 0"/>
  </joint>
  <link name="chassis">
    <visual>
      <origin xyz="0 0 0.085"/>
      <geometry>
        <mesh filename="file:///home/ros2iesus/ros2_ws/src/car_gps/rtk_gps_description/meshes/Chassis.stl" scale="0.001 0.001 0.001"/>
      </geometry>
      <material name="white"/>
    </visual>
    <collision>
      <origin xyz="0 0 0.085"/>
      <geometry>
        <box size="0.69804 0.325 0.17 "/>
      </geometry>
    </collision>
    <inertial>
      <mass value="19.928"/>
      <origin xyz="0 0 0"/>
      <inertia ixx="0.286" ixy="0.0" ixz="0.0" iyy="1.109" iyz="0.0" izz="1.227"/>
    </inertial>
  </link>
  <gazebo reference="chassis">
    <material>
            Gazebo/White
        </material>
  </gazebo>
  <!-- sensor joint -->
  <joint name="fixed" type="fixed">
    <parent link="base_link"/>
    <child link="sensor"/>
    <origin xyz="0.23 0 0.17"/>
  </joint>
  <!-- sensor Link -->
  <link name="sensor">
    <visual>
      <origin rpy="0 0 0" xyz="0 0 0.02"/>
      <geometry>
        <box size="0.135 0.11 0.04"/>
      </geometry>
      <material name="orange"/>
    </visual>
    <collision>
      <origin rpy="0 0 0" xyz="0 0 0.02"/>
      <geometry>
        <box size="0.135 0.11 0.04"/>
      </geometry>
    </collision>
    <inertial>
      <origin rpy="0 0 0" xyz="0 0 0.02"/>
      <mass value="1"/>
      <inertia ixx="1.0" ixy="0.0" ixz="0.0" iyy="1.0" iyz="0.0" izz="1.0"/>
    </inertial>
  </link>
  <gazebo reference="sensor">
    <material>Gazebo/Orange</material>
  </gazebo>
  <joint name="left_wheel_front_joint" type="continuous">
    <parent link="base_link"/>
    <child link="left_wheel_front_link"/>
    <origin xyz="0.175 0.1875 0"/>
    <axis xyz="0 1 0"/>
  </joint>
  <link name="left_wheel_front_link">
    <visual>
      <geometry>
        <mesh filename="file:///home/ros2iesus/ros2_ws/src/car_gps/rtk_gps_description/meshes/wheels.stl" scale="0.001 0.001 0.001"/>
      </geometry>
      <material name="black"/>
    </visual>
    <collision>
      <origin rpy="-1.5707963267948966 0 0" xyz="0 0 0"/>
      <geometry>
        <cylinder length="0.05" radius="0.1"/>
      </geometry>
    </collision>
    <inertial>
      <origin xyz="0 0 0"/>
      <mass value="1.420"/>
      <inertia ixx="0.004" ixy="0.0" ixz="0.0" iyy="0.008" iyz="0.0" izz="0.004"/>
    </inertial>
  </link>
  <gazebo reference="left_wheel_front_link">
    <material>Gazebo/Black</material>
    <mu1 value="0.35"/>
    <mu2 value="0.35"/>
  </gazebo>
  <joint name="left_wheel_back_joint" type="continuous">
    <parent link="base_link"/>
    <child link="left_wheel_back_link"/>
    <origin xyz="-0.175 0.1875 0"/>
    <axis xyz="0 1 0"/>
  </joint>
  <link name="left_wheel_back_link">
    <visual>
      <geometry>
        <mesh filename="file:///home/ros2iesus/ros2_ws/src/car_gps/rtk_gps_description/meshes/wheels.stl" scale="0.001 0.001 0.001"/>
      </geometry>
      <material name="black"/>
    </visual>
    <collision>
      <origin rpy="-1.5707963267948966 0 0" xyz="0 0 0"/>
      <geometry>
        <cylinder length="0.05" radius="0.1"/>
      </geometry>
    </collision>
    <inertial>
      <origin xyz="0 0 0"/>
      <mass value="1.420"/>
      <inertia ixx="0.004" ixy="0.0" ixz="0.0" iyy="0.008" iyz="0.0" izz="0.004"/>
    </inertial>
  </link>
  <gazebo reference="left_wheel_back_link">
    <material>Gazebo/Black</material>
    <mu1 value="0.35"/>
    <mu2 value="0.35"/>
  </gazebo>
  <joint name="right_wheel_front_joint" type="continuous">
    <parent link="base_link"/>
    <child link="right_wheel_front_link"/>
    <origin xyz="0.175 -0.1875 0"/>
    <axis xyz="0 1 0"/>
  </joint>
  <link name="right_wheel_front_link">
    <visual>
      <geometry>
        <mesh filename="file:///home/ros2iesus/ros2_ws/src/car_gps/rtk_gps_description/meshes/wheels.stl" scale="0.001 0.001 0.001"/>
      </geometry>
      <material name="black"/>
    </visual>
    <collision>
      <origin rpy="1.5707963267948966 0 0" xyz="0 0 0"/>
      <geometry>
        <cylinder length="0.05" radius="0.1"/>
      </geometry>
    </collision>
    <inertial>
      <origin xyz="0 0 0"/>
      <mass value="1.420"/>
      <inertia ixx="0.004" ixy="0.0" ixz="0.0" iyy="0.008" iyz="0.0" izz="0.004"/>
    </inertial>
  </link>
  <gazebo reference="right_wheel_front_link">
    <material>Gazebo/Black</material>
    <mu1 value="0.35"/>
    <mu2 value="0.35"/>
  </gazebo>
  <joint name="right_wheel_back_joint" type="continuous">
    <parent link="base_link"/>
    <child link="right_wheel_back_link"/>
    <origin xyz="-0.175 -0.1875 0"/>
    <axis xyz="0 1 0"/>
  </joint>
  <link name="right_wheel_back_link">
    <visual>
      <geometry>
        <mesh filename="file:///home/ros2iesus/ros2_ws/src/car_gps/rtk_gps_description/meshes/wheels.stl" scale="0.001 0.001 0.001"/>
      </geometry>
      <material name="black"/>
    </visual>
    <collision>
      <origin rpy="1.5707963267948966 0 0" xyz="0 0 0"/>
      <geometry>
        <cylinder length="0.05" radius="0.1"/>
      </geometry>
    </collision>
    <inertial>
      <origin xyz="0 0 0"/>
      <mass value="1.420"/>
      <inertia ixx="0.004" ixy="0.0" ixz="0.0" iyy="0.008" iyz="0.0" izz="0.004"/>
    </inertial>
  </link>
  <gazebo reference="right_wheel_back_link">
    <material>Gazebo/Black</material>
    <mu1 value="0.35"/>
    <mu2 value="0.35"/>
  </gazebo>
  <gazebo>
    <plugin filename="libgazebo_ros_joint_state_publisher.so" name="bytes_joint_state">
      <ros>
        <remapping>~/out:=joint_states</remapping>
      </ros>
      <update_rate>30</update_rate>
      <joint_name>left_wheel_front_joint</joint_name>
      <joint_name>left_wheel_back_joint</joint_name>
      <joint_name>right_wheel_front_joint</joint_name>
      <joint_name>right_wheel_back_joint</joint_name>
      <body_name>base_link</body_name>
      <topic_name>joint_states</topic_name>
    </plugin>
  </gazebo>
  <gazebo>
    <plugin filename="libhector_gazebo_ros_gps.so" name="gazebo_ros_gps">
      <updateRate>1.0</updateRate>
      <bodyName>sensor</bodyName>
      <frameId>sensor</frameId>
      <topicName>/cell/fix</topicName>
      <velocityTopicName>/cell/fix_velocity</velocityTopicName>
      <referenceLatitude>37.373669</referenceLatitude>
      <referenceLongitude>126.667134</referenceLongitude>
      <referenceHeading>90</referenceHeading>
      <referenceAltitude>0</referenceAltitude>
      <!--offset>0 0 0</offset-->
      <!--drift>0 0 0</drift-->
      <!--gaussianNoise>0 0 0</gaussianNoise-->
      <!--velocityDrift>0 0 0</velocityDrift-->
      <!--velocityGaussianNoise>0 0 0</velocityGaussianNoise-->
      <drift>0.003 0.003 0.003</drift>
      <gaussianNoise>0.15000000000000002 0.15000000000000002 0.15000000000000002</gaussianNoise>
      <velocityDrift>0.003 0.003 0.003</velocityDrift>
      <velocityGaussianNoise>0.15000000000000002 0.15000000000000002 0.15000000000000002</velocityGaussianNoise>
      <!--gaussianNoise>0.05 0.05 0.05</gaussianNoise-->
      <!--velocityDrift>0.001 0.001 0.001</velocityDrift-->
      <!--velocityGaussianNoise>0.05 0.05 0.05</velocityGaussianNoise-->
    </plugin>
  </gazebo>
  <gazebo>
    <plugin filename="libhector_gazebo_ros_gps.so" name="gazebo_ros_gps">
      <updateRate>4</updateRate>
      <bodyName>sensor</bodyName>
      <frameId>sensor</frameId>
      <topicName>/rtk</topicName>
      <velocityTopicName>/rtkvelocity</velocityTopicName>
      <referenceLatitude>37.373669</referenceLatitude>
      <referenceLongitude>126.667134</referenceLongitude>
      <referenceHeading>90</referenceHeading>
      <referenceAltitude>0</referenceAltitude>
      <offset>0 0 0</offset>
      <drift>0 0 0</drift>
      <gaussianNoise>0 0 0</gaussianNoise>
      <velocityDrift>0 0 0</velocityDrift>
      <velocityGaussianNoise>0 0 0</velocityGaussianNoise>
      <!--                <drift>0.001 0.001 0.001</drift>-->
      <!--                <gaussianNoise>0.05 0.05 0.05</gaussianNoise>-->
      <!--                <velocityDrift>0.001 0.001 0.001</velocityDrift>-->
      <!--                <velocityGaussianNoise>0.05 0.05 0.05</velocityGaussianNoise>-->
    </plugin>
  </gazebo>
  <gazebo>
    <!--plugin name="imu_plugin" filename="libgazebo_ros_imu.so"-->
    <plugin filename="libhector_gazebo_ros_imu.so" name="imu_plugin">
      <updateRate>2.0</updateRate>
      <boyName>sensor</boyName>
      <topicName>/handsfree/imu</topicName>
      <frameId>sensor</frameId>
      <accelGaussianNoise>0 0 0</accelGaussianNoise>
      <rateGaussianNoise>0 0 0</rateGaussianNoise>
      <yawGaussianNoise>0.0</yawGaussianNoise>
      <!--alwaysOn>true</alwaysOn>
      <bodyName>sensor</bodyName>
      <frameId>sensor</frameId>
      <topicName>imu/data</topicName>
      <serviceName>imu_service</serviceName>
      <gaussianNoise>0.0</gaussianNoise>
      <updateRate>20.0</updateRate-->
    </plugin>
  </gazebo>
  <gazebo>
    <plugin filename="libgazebo_ros_diff_drive.so" name="skid_steer_drive">
      <update_rate>100.0</update_rate>
      <num_wheel_pairs>2</num_wheel_pairs>
      <!-- wheels0-->
      <left_joint>left_wheel_front_joint</left_joint>
      <right_joint>right_wheel_front_joint</right_joint>
      <!-- wheels1-->
      <left_joint>left_wheel_back_joint</left_joint>
      <right_joint>right_wheel_back_joint</right_joint>
      <!-- kinematics -->
      <wheel_separation>0.3750</wheel_separation>
      <wheel_separation>0.3750</wheel_separation>
      <wheel_diameter>0.2</wheel_diameter>
      <wheel_diameter>0.2</wheel_diameter>
      <!-- limits -->
      <max_wheel_torque>20</max_wheel_torque>
      <MaxForce>5.0</MaxForce>
      <command_topic>cmd_vel</command_topic>
      <broadcast_tf>true</broadcast_tf>
      <odometry_topic>odom</odometry_topic>
      <odometry_frame>odom</odometry_frame>
      <robot_base_frame>base_link</robot_base_frame>
      <publish_odom>true</publish_odom>
      <publish_odom_tf>true</publish_odom_tf>
      <publish_wheel_tf>false</publish_wheel_tf>
    </plugin>
  </gazebo>
</robot>
